Workbook

Sheet 0. README
A1: NOVATECH ELECTRONICS | SUPPLY CHAIN ANALYTICS PROJECT
A2: An end to end inventory analytics model | Built by Kavish Shah
B4: ABOUT THIS PROJECT
B5: NovaTech Electronics is a fictional consumer electronics distributor created for this analysis.
B6: The model covers 500 SKUs across 10 categories, 3 regional distribution centers, and 10 suppliers,
B7: with 24 months of monthly demand history including holiday seasonality and year over year growth.
B8: Every analytical number in this workbook is a live Excel formula. Change an input and the entire model recalculates.
B10: HOW THE TABS FLOW
B11: 1. Master Data: the 500 SKU backbone (cost, lead time, supplier, stock position).
B12: 2. Demand History: 24 months of demand per SKU with visible Q4 spikes.
B13: 3. Demand Forecast: method matched to demand pattern, MAPE backtested over 6 months.
B14: 4. ABC XYZ Analysis: value concentration vs predictability, with the 9 box strategy matrix.
B15: 5. Replenishment Model: safety stock, reorder points, EOQ and order flags for all 500 SKUs.
B16: 6. Inventory Health: aging, turns, and the excess capital report.
... B30: The methodology, formulas, and analytical logic are exactly what I would apply to real company data.

Sheet 1. Master Data
A1: MASTER DATA | 500 SKUs
A2: Single source of truth: identity, sourcing, cost, lead time, status, stock position.
A4: SKU | B4: Product Name | C4: Category | D4: DC | E4: Supplier | F4: Unit Cost | G4: Lead Time Days | H4: Status | I4: On Hand | J4: Days Since Move | K4: Annual Usage
A5: NT10001 | B5: Nova X427 128GB | C5: Smartphones | D5: West DC | E5: Shenzhen Onyx Electronics | F5: 865 | G5: 17 | H5: Active | I5: 124 | J5: 53 | K5: 1141
A6: NT10002 | B6: Pulse 962 Dual SIM | C6: Smartphones | D6: East DC | E6: Pacific Semis | F6: 701 | G6: 44 | H6: Active | I6: 146 | J6: 48 | K6: 634
A7: NT10003 | B7: Nova Lite 936 64GB | C7: Smartphones | D7: West DC | E7: Shenzhen Onyx Electronics | F7: 261 | G7: 21 | H7: Active | I7: 181 | J7: 25 | K7: 1450
A8: NT10004 | B8: Nova Lite 315 64GB | C8: Smartphones | D8: West DC | E8: Pacific Semis | F8: 606 | G8: 39 | H8: Active | I8: 177 | J8: 29 | K8: 804
A9: NT10005 | B9: Pulse 753 Dual SIM | C9: Smartphones | D9: Central DC | E9: Shenzhen Onyx Electronics | F9: 598 | G9: 25 | H9: Active | I9: 61 | J9: 43 | K9: 422
A10: NT10006 | B10: Edge 244 5G 128GB | C10: Smartphones | D10: Central DC | E10: Pacific Semis | F10: 627 | G10: 35 | H10: Active | I10: 150 | J10: 68 | K10: 794
A11: NT10007 | B11: Pulse 667 Dual SIM | C11: Smartphones | D11: Central DC | E11: Pacific Semis | F11: 685 | G11: 36 | H11: Active | I11: 86 | J11: 16 | K11: 413
A12: NT10008 | B12: Edge 637 5G 128GB | C12: Smartphones | D12: West DC | E12: Pacific Semis | F12: 827 | G12: 41 | H12: Active | I12: 370 | J12: 69 | K12: 1629
A13: NT10009 | B13: Nova X689 128GB | C13: Smartphones | D13: West DC | E13: Shenzhen Onyx Electronics | F13: 382 | G13: 26 | H13: Active | I13: 86 | J13: 53 | K13: 593
A14: NT10010 | B14: Nova X834 128GB | C14: Smartphones | D14: West DC | E14: Pacific Semis | F14: 395 | G14: 42 | H14: Active | I14: 608 | J14: 30 | K14: 2758
A15: NT10011 | B15: Edge 790 5G 128GB | C15: Smartphones | D15: Central DC | E15: Pacific Semis | F15: 507 | G15: 43 | H15: Active | I15: 251 | J15: 53 | K15: 1094
A16: NT10012 | B16: Pulse 918 Dual SIM | C16: Smartphones | D16: East DC | E16: Pacific Semis | F16: 693 | G16: 41 | H16: Active | I16: 29 | J16: 6 | K16: 121
... A504: NT10500 | B504: Phone Case Clear V670 | C504: Accessories | D504: East DC | E504: Hanoi Assembly Works | F504: 28 | G504: 22 | H504: Active | I504: 277 | J504: 10 | K504: 2962
A506: FORMULA REFERENCE
A507: Static base data. Every other sheet links here or to Demand History, so changing a value here flows through the whole model.
A508: Annual Usage equals the sum of the last 12 months in Demand History (verified live on the ABC XYZ sheet).

Sheet 2. Demand History
A1: DEMAND HISTORY | 24 MONTHS
A2: Monthly unit demand per SKU, Jun 2024 to May 2026. Watch the Q4 holiday spikes.
A4: SKU | B4: Product Name | C4: Jun 24 | D4: Jul 24 | E4: Aug 24 | F4: Sep 24 | G4: Oct 24 | H4: Nov 24 | I4: Dec 24 | J4: Jan 25 | K4: Feb 25 | L4: Mar 25 | M4: Apr 25 | N4: May 25 | O4: Jun 25 | P4: Jul 25 | Q4: Aug 25 | R4: Sep 25 | S4: Oct 25 | T4: Nov 25 | U4: Dec 25 | V4: Jan 26 | W4: Feb 26 | X4: Mar 26 | Y4: Apr 26 | Z4: May 26 | AA4: Annual Last 12
A5: NT10001 | B5: Nova X427 128GB | C5: 82 | D5: 89 | E5: 71 | F5: 96 | G5: 90 | H5: 106 | I5: 164 | J5: 64 | K5: 75 | L5: 85 | M5: 87 | N5: 88 | O5: 99 | P5: 72 | Q5: 84 | R5: 87 | S5: 102 | T5: 148 | U5: 166 | V5: 60 | W5: 61 | X5: 85 | Y5: 98 | Z5: 79 | AA5: =SUM(O5:Z5) -> 1141
A6: NT10002 | B6: Pulse 962 Dual SIM | C6: 48 | D6: 49 | E6: 43 | F6: 46 | G6: 56 | H6: 71 | I6: 92 | J6: 34 | K6: 47 | L6: 44 | M6: 43 | N6: 53 | O6: 42 | P6: 49 | Q6: 40 | R6: 53 | S6: 60 | T6: 74 | U6: 89 | V6: 37 | W6: 35 | X6: 48 | Y6: 49 | Z6: 58 | AA6: =SUM(O6:Z6) -> 634
A7: NT10003 | B7: Nova Lite 936 64GB | C7: 106 | D7: 102 | E7: 91 | F7: 98 | G7: 129 | H7: 148 | I7: 206 | J7: 82 | K7: 82 | L7: 89 | M7: 109 | N7: 111 | O7: 109 | P7: 107 | Q7: 98 | R7: 110 | S7: 130 | T7: 174 | U7: 217 | V7: 87 | W7: 95 | X7: 92 | Y7: 109 | Z7: 122 | AA7: =SUM(O7:Z7) -> 1450
A8: NT10004 | B8: Nova Lite 315 64GB | C8: 57 | D8: 59 | E8: 49 | F8: 55 | G8: 65 | H8: 87 | I8: 98 | J8: 45 | K8: 45 | L8: 59 | M8: 67 | N8: 64 | O8: 61 | P8: 52 | Q8: 53 | R8: 61 | S8: 75 | T8: 92 | U8: 132 | V8: 37 | W8: 54 | X8: 69 | Y8: 53 | Z8: 65 | AA8: =SUM(O8:Z8) -> 804
A9: NT10005 | B9: Pulse 753 Dual SIM | C9: 29 | D9: 29 | E9: 30 | F9: 29 | G9: 36 | H9: 47 | I9: 59 | J9: 22 | K9: 26 | L9: 26 | M9: 31 | N9: 32 | O9: 30 | P9: 30 | Q9: 29 | R9: 30 | S9: 35 | T9: 49 | U9: 61 | V9: 26 | W9: 29 | X9: 32 | Y9: 35 | Z9: 36 | AA9: =SUM(O9:Z9) -> 422
A10: NT10006 | B10: Edge 244 5G 128GB | C10: 53 | D10: 49 | E10: 46 | F10: 66 | G10: 71 | H10: 79 | I10: 100 | J10: 49 | K10: 52 | L10: 55 | M10: 66 | N10: 63 | O10: 59 | P10: 63 | Q10: 60 | R10: 60 | S10: 66 | T10: 96 | U10: 107 | V10: 35 | W10: 57 | X10: 51 | Y10: 63 | Z10: 77 | AA10: =SUM(O10:Z10) -> 794
A11: NT10007 | B11: Pulse 667 Dual SIM | C11: 33 | D11: 31 | E11: 21 | F11: 27 | G11: 30 | H11: 45 | I11: 60 | J11: 24 | K11: 23 | L11: 30 | M11: 30 | N11: 30 | O11: 31 | P11: 28 | Q11: 31 | R11: 31 | S11: 34 | T11: 44 | U11: 69 | V11: 26 | W11: 22 | X11: 31 | Y11: 36 | Z11: 30 | AA11: =SUM(O11:Z11) -> 413
A12: NT10008 | B12: Edge 637 5G 128GB | C12: 117 | D12: 116 | E12: 98 | F12: 127 | G12: 145 | H12: 195 | I12: 240 | J12: 99 | K12: 99 | L12: 122 | M12: 120 | N12: 140 | O12: 87 | P12: 122 | Q12: 106 | R12: 114 | S12: 158 | T12: 208 | U12: 254 | V12: 86 | W12: 94 | X12: 120 | Y12: 136 | Z12: 144 | AA12: =SUM(O12:Z12) -> 1629
A13: NT10009 | B13: Nova X689 128GB | C13: 41 | D13: 42 | E13: 40 | F13: 40 | G13: 44 | H13: 64 | I13: 79 | J13: 31 | K13: 33 | L13: 37 | M13: 41 | N13: 40 | O13: 38 | P13: 45 | Q13: 42 | R13: 49 | S13: 58 | T13: 63 | U13: 82 | V13: 32 | W13: 43 | X13: 43 | Y13: 45 | Z13: 53 | AA13: =SUM(O13:Z13) -> 593
A14: NT10010 | B14: Nova X834 128GB | C14: 202 | D14: 193 | E14: 178 | F14: 188 | G14: 212 | H14: 301 | I14: 371 | J14: 168 | K14: 178 | L14: 158 | M14: 189 | N14: 211 | O14: 199 | P14: 220 | Q14: 213 | R14: 192 | S14: 220 | T14: 296 | U14: 435 | V14: 164 | W14: 177 | X14: 227 | Y14: 198 | Z14: 217 | AA14: =SUM(O14:Z14) -> 2758
A15: NT10011 | B15: Edge 790 5G 128GB | C15: 77 | D15: 86 | E15: 83 | F15: 77 | G15: 88 | H15: 88 | I15: 134 | J15: 61 | K15: 65 | L15: 83 | M15: 83 | N15: 84 | O15: 78 | P15: 98 | Q15: 71 | R15: 71 | S15: 84 | T15: 122 | U15: 172 | V15: 63 | W15: 75 | X15: 85 | Y15: 84 | Z15: 91 | AA15: =SUM(O15:Z15) -> 1094
A16: NT10012 | B16: Pulse 918 Dual SIM | C16: 7 | D16: 9 | E16: 8 | F16: 8 | G16: 9 | H16: 11 | I16: 16 | J16: 6 | K16: 8 | L16: 8 | M16: 10 | N16: 10 | O16: 8 | P16: 8 | Q16: 10 | R16: 10 | S16: 11 | T16: 14 | U16: 16 | V16: 6 | W16: 8 | X16: 8 | Y16: 11 | Z16: 11 | AA16: =SUM(O16:Z16) -> 121
... A504: NT10500 | B504: Phone Case Clear V670 | C504: 223 | D504: 234 | E504: 209 | F504: 243 | G504: 238 | H504: 237 | I504: 211 | J504: 232 | K504: 262 | L504: 256 | M504: 236 | N504: 235 | O504: 257 | P504: 255 | Q504: 267 | R504: 231 | S504: 250 | T504: 249 | U504: 221 | V504: 233 | W504: 251 | X504: 225 | Y504: 254 | Z504: 269 | AA504: =SUM(O504:Z504) -> 2962
B505: TOTAL MONTHLY DEMAND | C505: =SUM(C5:C504) -> 65396 | D505: =SUM(D5:D504) -> 63137 | E505: =SUM(E5:E504) -> 60661 | F505: =SUM(F5:F504) -> 62809 | G505: =SUM(G5:G504) -> 68866 | H505: =SUM(H5:H504) -> 81077 | I505: =SUM(I5:I504) -> 91895 | J505: =SUM(J5:J504) -> 56009 | ... Z505: =SUM(Z5:Z504) -> 71104
A527: FORMULA REFERENCE
A528: Annual Last 12 = SUM of Jun 25 through May 26.
A529: The totals row feeds the demand trend chart. Q4 peaks (Nov, Dec) and the Jan dip are visible: classic consumer electronics seasonality.

Sheet 3. Demand Forecast
A1: DEMAND FORECAST | METHOD MATCHED TO PATTERN
A2: Seasonal SKUs use Seasonal Naive, stable SKUs use Moving Average. MAPE backtested over the last 6 months.
A4: SKU | B4: Product Name | C4: Category | D4: Seasonal | E4: Method | F4: Avg Monthly | G4: Std Dev | H4: CV | I4: YoY Growth | J4: Forecast Jun 26 | K4: MAPE | L4: Err Dec | M4: Err Jan | N4: Err Feb | O4: Err Mar | P4: Err Apr | Q4: Err May
A5: ='2. Demand History'!A5 -> NT10001 | B5: ='2. Demand History'!B5 -> Nova X427 128GB | C5: ='1. Master Data'!C5 -> Smartphones | D5: Yes | E5: =IF(D5="Yes","Seasonal Naive","Moving Avg 3") -> Seasonal Naive | F5: =ROUND(AVERAGE('2. Demand History'!O5:Z5),1) -> 95.1 | G5: =ROUND(STDEV('2. Demand History'!O5:Z5),1) -> 32.2 | H5: =IF(F5=0,0,ROUND(G5/F5,2)) -> 0.34 | I5: =ROUND(SUM('2. Demand History'!O5:Z5)/MAX(SUM('2. Demand History'!C5:N5),1),2) -> 1.04 | J5: =IF(D5="Yes",ROUND('2. Demand History'!O5*I5,0),ROUND(AVERAGE('2. Demand History'!X5:Z5),0)) -> 103 | K5: =ROUND(AVERAGE(L5:Q5),3) -> 0.089 | L5: =ROUND(ABS('2. Demand History'!U5-IF($D5="Yes",'2. Demand History'!I5,AVERAGE('2. Demand History'!R5:T5)))/MAX('2. Demand History'!U5,1),3) -> 0.012 | M5: =ROUND(ABS('2. Demand History'!V5-IF($D5="Yes",'2. Demand History'!J5,AVERAGE('2. Demand History'!S5:U5)))/MAX('2. Demand History'!V5,1),3) -> 0.067 | N5: =ROUND(ABS('2. Demand History'!W5-IF($D5="Yes",'2. Demand History'!K5,AVERAGE('2. Demand History'!T5:V5)))/MAX('2. Demand History'!W5,1),3) -> 0.23 | O5: =ROUND(ABS('2. Demand History'!X5-IF($D5="Yes",'2. Demand History'!L5,AVERAGE('2. Demand History'!U5:W5)))/MAX('2. Demand History'!X5,1),3) -> 0 | P5: =ROUND(ABS('2. Demand History'!Y5-IF($D5="Yes",'2. Demand History'!M5,AVERAGE('2. Demand History'!V5:X5)))/MAX('2. Demand History'!Y5,1),3) -> 0.112 | Q5: =ROUND(ABS('2. Demand History'!Z5-IF($D5="Yes",'2. Demand History'!N5,AVERAGE('2. Demand History'!W5:Y5)))/MAX('2. Demand History'!Z5,1),3) -> 0.114
A6: ='2. Demand History'!A6 -> NT10002 | B6: ='2. Demand History'!B6 -> Pulse 962 Dual SIM | C6: ='1. Master Data'!C6 -> Smartphones | D6: Yes | E6: =IF(D6="Yes","Seasonal Naive","Moving Avg 3") -> Seasonal Naive | F6: =ROUND(AVERAGE('2. Demand History'!O6:Z6),1) -> 52.8 | G6: =ROUND(STDEV('2. Demand History'!O6:Z6),1) -> 15.8 | H6: =IF(F6=0,0,ROUND(G6/F6,2)) -> 0.3 | I6: =ROUND(SUM('2. Demand History'!O6:Z6)/MAX(SUM('2. Demand History'!C6:N6),1),2) -> 1.01 | J6: =IF(D6="Yes",ROUND('2. Demand History'!O6*I6,0),ROUND(AVERAGE('2. Demand History'!X6:Z6),0)) -> 42 | K6: =ROUND(AVERAGE(L6:Q6),3) -> 0.125 | L6: =ROUND(ABS('2. Demand History'!U6-IF($D6="Yes",'2. Demand History'!I6,AVERAGE('2. Demand History'!R6:T6)))/MAX('2. Demand History'!U6,1),3) -> 0.034 | M6: =ROUND(ABS('2. Demand History'!V6-IF($D6="Yes",'2. Demand History'!J6,AVERAGE('2. Demand History'!S6:U6)))/MAX('2. Demand History'!V6,1),3) -> 0.081 | N6: =ROUND(ABS('2. Demand History'!W6-IF($D6="Yes",'2. Demand History'!K6,AVERAGE('2. Demand History'!T6:V6)))/MAX('2. Demand History'!W6,1),3) -> 0.343 | O6: =ROUND(ABS('2. Demand History'!X6-IF($D6="Yes",'2. Demand History'!L6,AVERAGE('2. Demand History'!U6:W6)))/MAX('2. Demand History'!X6,1),3) -> 0.083 | P6: =ROUND(ABS('2. Demand History'!Y6-IF($D6="Yes",'2. Demand History'!M6,AVERAGE('2. Demand History'!V6:X6)))/MAX('2. Demand History'!Y6,1),3) -> 0.122 | Q6: =ROUND(ABS('2. Demand History'!Z6-IF($D6="Yes",'2. Demand History'!N6,AVERAGE('2. Demand History'!W6:Y6)))/MAX('2. Demand History'!Z6,1),3) -> 0.086
A7: ='2. Demand History'!A7 -> NT10003 | B7: ='2. Demand History'!B7 -> Nova Lite 936 64GB | C7: ='1. Master Data'!C7 -> Smartphones | D7: Yes | E7: =IF(D7="Yes","Seasonal Naive","Moving Avg 3") -> Seasonal Naive | F7: =ROUND(AVERAGE('2. Demand History'!O7:Z7),1) -> 120.8 | G7: =ROUND(STDEV('2. Demand History'!O7:Z7),1) -> 38 | H7: =IF(F7=0,0,ROUND(G7/F7,2)) -> 0.31 | I7: =ROUND(SUM('2. Demand History'!O7:Z7)/MAX(SUM('2. Demand History'!C7:N7),1),2) -> 1.07 | J7: =IF(D7="Yes",ROUND('2. Demand History'!O7*I7,0),ROUND(AVERAGE('2. Demand History'!X7:Z7),0)) -> 117 | K7: =ROUND(AVERAGE(L7:Q7),3) -> 0.061 | L7: =ROUND(ABS('2. Demand History'!U7-IF($D7="Yes",'2. Demand History'!I7,AVERAGE('2. Demand History'!R7:T7)))/MAX('2. Demand History'!U7,1),3) -> 0.051 | M7: =ROUND(ABS('2. Demand History'!V7-IF($D7="Yes",'2. Demand History'!J7,AVERAGE('2. Demand History'!S7:U7)))/MAX('2. Demand History'!V7,1),3) -> 0.057 | N7: =ROUND(ABS('2. Demand History'!W7-IF($D7="Yes",'2. Demand History'!K7,AVERAGE('2. Demand History'!T7:V7)))/MAX('2. Demand History'!W7,1),3) -> 0.137 | O7: =ROUND(ABS('2. Demand History'!X7-IF($D7="Yes",'2. Demand History'!L7,AVERAGE('2. Demand History'!U7:W7)))/MAX('2. Demand History'!X7,1),3) -> 0.033 | P7: =ROUND(ABS('2. Demand History'!Y7-IF($D7="Yes",'2. Demand History'!M7,AVERAGE('2. Demand History'!V7:X7)))/MAX('2. Demand History'!Y7,1),3) -> 0 | Q7: =ROUND(ABS('2. Demand History'!Z7-IF($D7="Yes",'2. Demand History'!N7,AVERAGE('2. Demand History'!W7:Y7)))/MAX('2. Demand History'!Z7,1),3) -> 0.09
A8: ='2. Demand History'!A8 -> NT10004 | B8: ='2. Demand History'!B8 -> Nova Lite 315 64GB | C8: ='1. Master Data'!C8 -> Smartphones | D8: Yes | E8: =IF(D8="Yes","Seasonal Naive","Moving Avg 3") -> Seasonal Naive | F8: =ROUND(AVERAGE('2. Demand History'!O8:Z8),1) -> 67 | G8: =ROUND(STDEV('2. Demand History'!O8:Z8),1) -> 24.6 | H8: =IF(F8=0,0,ROUND(G8/F8,2)) -> 0.37 | I8: =ROUND(SUM('2. Demand History'!O8:Z8)/MAX(SUM('2. Demand History'!C8:N8),1),2) -> 1.07 | J8: =IF(D8="Yes",ROUND('2. Demand History'!O8*I8,0),ROUND(AVERAGE('2. Demand History'!X8:Z8),0)) -> 65 | K8: =ROUND(AVERAGE(L8:Q8),3) -> 0.178 | L8: =ROUND(ABS('2. Demand History'!U8-IF($D8="Yes",'2. Demand History'!I8,AVERAGE('2. Demand History'!R8:T8)))/MAX('2. Demand History'!U8,1),3) -> 0.258 | M8: =ROUND(ABS('2. Demand History'!V8-IF($D8="Yes",'2. Demand History'!J8,AVERAGE('2. Demand History'!S8:U8)))/MAX('2. Demand History'!V8,1),3) -> 0.216 | N8: =ROUND(ABS('2. Demand History'!W8-IF($D8="Yes",'2. Demand History'!K8,AVERAGE('2. Demand History'!T8:V8)))/MAX('2. Demand History'!W8,1),3) -> 0.167 | O8: =ROUND(ABS('2. Demand History'!X8-IF($D8="Yes",'2. Demand History'!L8,AVERAGE('2. Demand History'!U8:W8)))/MAX('2. Demand History'!X8,1),3) -> 0.145 | P8: =ROUND(ABS('2. Demand History'!Y8-IF($D8="Yes",'2. Demand History'!M8,AVERAGE('2. Demand History'!V8:X8)))/MAX('2. Demand History'!Y8,1),3) -> 0.264 | Q8: =ROUND(ABS('2. Demand History'!Z8-IF($D8="Yes",'2. Demand History'!N8,AVERAGE('2. Demand History'!W8:Y8)))/MAX('2. Demand History'!Z8,1),3) -> 0.015
A9: ='2. Demand History'!A9 -> NT10005 | B9: ='2. Demand History'!B9 -> Pulse 753 Dual SIM | C9: ='1. Master Data'!C9 -> Smartphones | D9: Yes | E9: =IF(D9="Yes","Seasonal Naive","Moving Avg 3") -> Seasonal Naive | F9: =ROUND(AVERAGE('2. Demand History'!O9:Z9),1) -> 35.2 | G9: =ROUND(STDEV('2. Demand History'!O9:Z9),1) -> 10 | H9: =IF(F9=0,0,ROUND(G9/F9,2)) -> 0.28 | I9: =ROUND(SUM('2. Demand History'!O9:Z9)/MAX(SUM('2. Demand History'!C9:N9),1),2) -> 1.07 | J9: =IF(D9="Yes",ROUND('2. Demand History'!O9*I9,0),ROUND(AVERAGE('2. Demand History'!X9:Z9),0)) -> 32 | K9: =ROUND(AVERAGE(L9:Q9),3) -> 0.117 | L9: =ROUND(ABS('2. Demand History'!U9-IF($D9="Yes",'2. Demand History'!I9,AVERAGE('2. Demand History'!R9:T9)))/MAX('2. Demand History'!U9,1),3) -> 0.033 | M9: =ROUND(ABS('2. Demand History'!V9-IF($D9="Yes",'2. Demand History'!J9,AVERAGE('2. Demand History'!S9:U9)))/MAX('2. Demand History'!V9,1),3) -> 0.154 | N9: =ROUND(ABS('2. Demand History'!W9-IF($D9="Yes",'2. Demand History'!K9,AVERAGE('2. Demand History'!T9:V9)))/MAX('2. Demand History'!W9,1),3) -> 0.103 | O9: =ROUND(ABS('2. Demand History'!X9-IF($D9="Yes",'2. Demand History'!L9,AVERAGE('2. Demand History'!U9:W9)))/MAX('2. Demand History'!X9,1),3) -> 0.188 | P9: =ROUND(ABS('2. Demand History'!Y9-IF($D9="Yes",'2. Demand History'!M9,AVERAGE('2. Demand History'!V9:X9)))/MAX('2. Demand History'!Y9,1),3) -> 0.114 | Q9: =ROUND(ABS('2. Demand History'!Z9-IF($D9="Yes",'2. Demand History'!N9,AVERAGE('2. Demand History'!W9:Y9)))/MAX('2. Demand History'!Z9,1),3) -> 0.111
A10: ='2. Demand History'!A10 -> NT10006 | B10: ='2. Demand History'!B10 -> Edge 244 5G 128GB | C10: ='1. Master Data'!C10 -> Smartphones | D10: Yes | E10: =IF(D10="Yes","Seasonal Naive","Moving Avg 3") -> Seasonal Naive | F10: =ROUND(AVERAGE('2. Demand History'!O10:Z10),1) -> 66.2 | G10: =ROUND(STDEV('2. Demand History'!O10:Z10),1) -> 19.3 | H10: =IF(F10=0,0,ROUND(G10/F10,2)) -> 0.29 | I10: =ROUND(SUM('2. Demand History'!O10:Z10)/MAX(SUM('2. Demand History'!C10:N10),1),2) -> 1.06 | J10: =IF(D10="Yes",ROUND('2. Demand History'!O10*I10,0),ROUND(AVERAGE('2. Demand History'!X10:Z10),0)) -> 63 | K10: =ROUND(AVERAGE(L10:Q10),3) -> 0.144 | L10: =ROUND(ABS('2. Demand History'!U10-IF($D10="Yes",'2. Demand History'!I10,AVERAGE('2. Demand History'!R10:T10)))/MAX('2. Demand History'!U10,1),3) -> 0.065 | M10: =ROUND(ABS('2. Demand History'!V10-IF($D10="Yes",'2. Demand History'!J10,AVERAGE('2. Demand History'!S10:U10)))/MAX('2. Demand History'!V10,1),3) -> 0.4 | N10: =ROUND(ABS('2. Demand History'!W10-IF($D10="Yes",'2. Demand History'!K10,AVERAGE('2. Demand History'!T10:V10)))/MAX('2. Demand History'!W10,1),3) -> 0.088 | O10: =ROUND(ABS('2. Demand History'!X10-IF($D10="Yes",'2. Demand History'!L10,AVERAGE('2. Demand History'!U10:W10)))/MAX('2. Demand History'!X10,1),3) -> 0.078 | P10: =ROUND(ABS('2. Demand History'!Y10-IF($D10="Yes",'2. Demand History'!M10,AVERAGE('2. Demand History'!V10:X10)))/MAX('2. Demand History'!Y10,1),3) -> 0.048 | Q10: =ROUND(ABS('2. Demand History'!Z10-IF($D10="Yes",'2. Demand History'!N10,AVERAGE('2. Demand History'!W10:Y10)))/MAX('2. Demand History'!Z10,1),3) -> 0.182
A11: ='2. Demand History'!A11 -> NT10007 | B11: ='2. Demand History'!B11 -> Pulse 667 Dual SIM | C11: ='1. Master Data'!C11 -> Smartphones | D11: Yes | E11: =IF(D11="Yes","Seasonal Naive","Moving Avg 3") -> Seasonal Naive | F11: =ROUND(AVERAGE('2. Demand History'!O11:Z11),1) -> 34.4 | G11: =ROUND(STDEV('2. Demand History'!O11:Z11),1) -> 12.1 | H11: =IF(F11=0,0,ROUND(G11/F11,2)) -> 0.35 | I11: =ROUND(SUM('2. Demand History'!O11:Z11)/MAX(SUM('2. Demand History'!C11:N11),1),2) -> 1.08 | J11: =IF(D11="Yes",ROUND('2. Demand History'!O11*I11,0),ROUND(AVERAGE('2. Demand History'!X11:Z11),0)) -> 33 | K11: =ROUND(AVERAGE(L11:Q11),3) -> 0.075 | L11: =ROUND(ABS('2. Demand History'!U11-IF($D11="Yes",'2. Demand History'!I11,AVERAGE('2. Demand History'!R11:T11)))/MAX('2. Demand History'!U11,1),3) -> 0.13 | M11: =ROUND(ABS('2. Demand History'!V11-IF($D11="Yes",'2. Demand History'!J11,AVERAGE('2. Demand History'!S11:U11)))/MAX('2. Demand History'!V11,1),3) -> 0.077 | N11: =ROUND(ABS('2. Demand History'!W11-IF($D11="Yes",'2. Demand History'!K11,AVERAGE('2. Demand History'!T11:V11)))/MAX('2. Demand History'!W11,1),3) -> 0.045 | O11: =ROUND(ABS('2. Demand History'!X11-IF($D11="Yes",'2. Demand History'!L11,AVERAGE('2. Demand History'!U11:W11)))/MAX('2. Demand History'!X11,1),3) -> 0.032 | P11: =ROUND(ABS('2. Demand History'!Y11-IF($D11="Yes",'2. Demand History'!M11,AVERAGE('2. Demand History'!V11:X11)))/MAX('2. Demand History'!Y11,1),3) -> 0.167 | Q11: =ROUND(ABS('2. Demand History'!Z11-IF($D11="Yes",'2. Demand History'!N11,AVERAGE('2. Demand History'!W11:Y11)))/MAX('2. Demand History'!Z11,1),3) -> 0
A12: ='2. Demand History'!A12 -> NT10008 | B12: ='2. Demand History'!B12 -> Edge 637 5G 128GB | C12: ='1. Master Data'!C12 -> Smartphones | D12: Yes | E12: =IF(D12="Yes","Seasonal Naive","Moving Avg 3") -> Seasonal Naive | F12: =ROUND(AVERAGE('2. Demand History'!O12:Z12),1) -> 135.8 | G12: =ROUND(STDEV('2. Demand History'!O12:Z12),1) -> 50.6 | H12: =IF(F12=0,0,ROUND(G12/F12,2)) -> 0.37 | I12: =ROUND(SUM('2. Demand History'!O12:Z12)/MAX(SUM('2. Demand History'!C12:N12),1),2) -> 1.01 | J12: =IF(D12="Yes",ROUND('2. Demand History'!O12*I12,0),ROUND(AVERAGE('2. Demand History'!X12:Z12),0)) -> 88 | K12: =ROUND(AVERAGE(L12:Q12),3) -> 0.07 | L12: =ROUND(ABS('2. Demand History'!U12-IF($D12="Yes",'2. Demand History'!I12,AVERAGE('2. Demand History'!R12:T12)))/MAX('2. Demand History'!U12,1),3) -> 0.055 | M12: =ROUND(ABS('2. Demand History'!V12-IF($D12="Yes",'2. Demand History'!J12,AVERAGE('2. Demand History'!S12:U12)))/MAX('2. Demand History'!V12,1),3) -> 0.151 | N12: =ROUND(ABS('2. Demand History'!W12-IF($D12="Yes",'2. Demand History'!K12,AVERAGE('2. Demand History'!T12:V12)))/MAX('2. Demand History'!W12,1),3) -> 0.053 | O12: =ROUND(ABS('2. Demand History'!X12-IF($D12="Yes",'2. Demand History'!L12,AVERAGE('2. Demand History'!U12:W12)))/MAX('2. Demand History'!X12,1),3) -> 0.017 | P12: =ROUND(ABS('2. Demand History'!Y12-IF($D12="Yes",'2. Demand History'!M12,AVERAGE('2. Demand History'!V12:X12)))/MAX('2. Demand History'!Y12,1),3) -> 0.118 | Q12: =ROUND(ABS('2. Demand History'!Z12-IF($D12="Yes",'2. Demand History'!N12,AVERAGE('2. Demand History'!W12:Y12)))/MAX('2. Demand History'!Z12,1),3) -> 0.028
A13: ='2. Demand History'!A13 -> NT10009 | B13: ='2. Demand History'!B13 -> Nova X689 128GB | C13: ='1. Master Data'!C13 -> Smartphones | D13: Yes | E13: =IF(D13="Yes","Seasonal Naive","Moving Avg 3") -> Seasonal Naive | F13: =ROUND(AVERAGE('2. Demand History'!O13:Z13),1) -> 49.4 | G13: =ROUND(STDEV('2. Demand History'!O13:Z13),1) -> 13.3 | H13: =IF(F13=0,0,ROUND(G13/F13,2)) -> 0.27 | I13: =ROUND(SUM('2. Demand History'!O13:Z13)/MAX(SUM('2. Demand History'!C13:N13),1),2) -> 1.11 | J13: =IF(D13="Yes",ROUND('2. Demand History'!O13*I13,0),ROUND(AVERAGE('2. Demand History'!X13:Z13),0)) -> 42 | K13: =ROUND(AVERAGE(L13:Q13),3) -> 0.129 | L13: =ROUND(ABS('2. Demand History'!U13-IF($D13="Yes",'2. Demand History'!I13,AVERAGE('2. Demand History'!R13:T13)))/MAX('2. Demand History'!U13,1),3) -> 0.037 | M13: =ROUND(ABS('2. Demand History'!V13-IF($D13="Yes",'2. Demand History'!J13,AVERAGE('2. Demand History'!S13:U13)))/MAX('2. Demand History'!V13,1),3) -> 0.031 | N13: =ROUND(ABS('2. Demand History'!W13-IF($D13="Yes",'2. Demand History'!K13,AVERAGE('2. Demand History'!T13:V13)))/MAX('2. Demand History'!W13,1),3) -> 0.233 | O13: =ROUND(ABS('2. Demand History'!X13-IF($D13="Yes",'2. Demand History'!L13,AVERAGE('2. Demand History'!U13:W13)))/MAX('2. Demand History'!X13,1),3) -> 0.14 | P13: =ROUND(ABS('2. Demand History'!Y13-IF($D13="Yes",'2. Demand History'!M13,AVERAGE('2. Demand History'!V13:X13)))/MAX('2. Demand History'!Y13,1),3) -> 0.089 | Q13: =ROUND(ABS('2. Demand History'!Z13-IF($D13="Yes",'2. Demand History'!N13,AVERAGE('2. Demand History'!W13:Y13)))/MAX('2. Demand History'!Z13,1),3) -> 0.245
A14: ='2. Demand History'!A14 -> NT10010 | B14: ='2. Demand History'!B14 -> Nova X834 128GB | C14: ='1. Master Data'!C14 -> Smartphones | D14: Yes | E14: =IF(D14="Yes","Seasonal Naive","Moving Avg 3") -> Seasonal Naive | F14: =ROUND(AVERAGE('2. Demand History'!O14:Z14),1) -> 229.8 | G14: =ROUND(STDEV('2. Demand History'!O14:Z14),1) -> 72.4 | H14: =IF(F14=0,0,ROUND(G14/F14,2)) -> 0.32 | I14: =ROUND(SUM('2. Demand History'!O14:Z14)/MAX(SUM('2. Demand History'!C14:N14),1),2) -> 1.08 | J14: =IF(D14="Yes",ROUND('2. Demand History'!O14*I14,0),ROUND(AVERAGE('2. Demand History'!X14:Z14),0)) -> 215 | K14: =ROUND(AVERAGE(L14:Q14),3) -> 0.092 | L14: =ROUND(ABS('2. Demand History'!U14-IF($D14="Yes",'2. Demand History'!I14,AVERAGE('2. Demand History'!R14:T14)))/MAX('2. Demand History'!U14,1),3) -> 0.147 | M14: =ROUND(ABS('2. Demand History'!V14-IF($D14="Yes",'2. Demand History'!J14,AVERAGE('2. Demand History'!S14:U14)))/MAX('2. Demand History'!V14,1),3) -> 0.024 | N14: =ROUND(ABS('2. Demand History'!W14-IF($D14="Yes",'2. Demand History'!K14,AVERAGE('2. Demand History'!T14:V14)))/MAX('2. Demand History'!W14,1),3) -> 0.006 | O14: =ROUND(ABS('2. Demand History'!X14-IF($D14="Yes",'2. Demand History'!L14,AVERAGE('2. Demand History'!U14:W14)))/MAX('2. Demand History'!X14,1),3) -> 0.304 | P14: =ROUND(ABS('2. Demand History'!Y14-IF($D14="Yes",'2. Demand History'!M14,AVERAGE('2. Demand History'!V14:X14)))/MAX('2. Demand History'!Y14,1),3) -> 0.045 | Q14: =ROUND(ABS('2. Demand History'!Z14-IF($D14="Yes",'2. Demand History'!N14,AVERAGE('2. Demand History'!W14:Y14)))/MAX('2. Demand History'!Z14,1),3) -> 0.028
A15: ='2. Demand History'!A15 -> NT10011 | B15: ='2. Demand History'!B15 -> Edge 790 5G 128GB | C15: ='1. Master Data'!C15 -> Smartphones | D15: Yes | E15: =IF(D15="Yes","Seasonal Naive","Moving Avg 3") -> Seasonal Naive | F15: =ROUND(AVERAGE('2. Demand History'!O15:Z15),1) -> 91.2 | G15: =ROUND(STDEV('2. Demand History'!O15:Z15),1) -> 29.7 | H15: =IF(F15=0,0,ROUND(G15/F15,2)) -> 0.33 | I15: =ROUND(SUM('2. Demand History'!O15:Z15)/MAX(SUM('2. Demand History'!C15:N15),1),2) -> 1.08 | J15: =IF(D15="Yes",ROUND('2. Demand History'!O15*I15,0),ROUND(AVERAGE('2. Demand History'!X15:Z15),0)) -> 84 | K15: =ROUND(AVERAGE(L15:Q15),3) -> 0.083 | L15: =ROUND(ABS('2. Demand History'!U15-IF($D15="Yes",'2. Demand History'!I15,AVERAGE('2. Demand History'!R15:T15)))/MAX('2. Demand History'!U15,1),3) -> 0.221 | M15: =ROUND(ABS('2. Demand History'!V15-IF($D15="Yes",'2. Demand History'!J15,AVERAGE('2. Demand History'!S15:U15)))/MAX('2. Demand History'!V15,1),3) -> 0.032 | N15: =ROUND(ABS('2. Demand History'!W15-IF($D15="Yes",'2. Demand History'!K15,AVERAGE('2. Demand History'!T15:V15)))/MAX('2. Demand History'!W15,1),3) -> 0.133 | O15: =ROUND(ABS('2. Demand History'!X15-IF($D15="Yes",'2. Demand History'!L15,AVERAGE('2. Demand History'!U15:W15)))/MAX('2. Demand History'!X15,1),3) -> 0.024 | P15: =ROUND(ABS('2. Demand History'!Y15-IF($D15="Yes",'2. Demand History'!M15,AVERAGE('2. Demand History'!V15:X15)))/MAX('2. Demand History'!Y15,1),3) -> 0.012 | Q15: =ROUND(ABS('2. Demand History'!Z15-IF($D15="Yes",'2. Demand History'!N15,AVERAGE('2. Demand History'!W15:Y15)))/MAX('2. Demand History'!Z15,1),3) -> 0.077
A16: ='2. Demand History'!A16 -> NT10012 | B16: ='2. Demand History'!B16 -> Pulse 918 Dual SIM | C16: ='1. Master Data'!C16 -> Smartphones | D16: Yes | E16: =IF(D16="Yes","Seasonal Naive","Moving Avg 3") -> Seasonal Naive | F16: =ROUND(AVERAGE('2. Demand History'!O16:Z16),1) -> 10.1 | G16: =ROUND(STDEV('2. Demand History'!O16:Z16),1) -> 2.8 | H16: =IF(F16=0,0,ROUND(G16/F16,2)) -> 0.28 | I16: =ROUND(SUM('2. Demand History'!O16:Z16)/MAX(SUM('2. Demand History'!C16:N16),1),2) -> 1.1 | J16: =IF(D16="Yes",ROUND('2. Demand History'!O16*I16,0),ROUND(AVERAGE('2. Demand History'!X16:Z16),0)) -> 9 | K16: =ROUND(AVERAGE(L16:Q16),3) -> 0.03 | L16: =ROUND(ABS('2. Demand History'!U16-IF($D16="Yes",'2. Demand History'!I16,AVERAGE('2. Demand History'!R16:T16)))/MAX('2. Demand History'!U16,1),3) -> 0 | M16: =ROUND(ABS('2. Demand History'!V16-IF($D16="Yes",'2. Demand History'!J16,AVERAGE('2. Demand History'!S16:U16)))/MAX('2. Demand History'!V16,1),3) -> 0 | N16: =ROUND(ABS('2. Demand History'!W16-IF($D16="Yes",'2. Demand History'!K16,AVERAGE('2. Demand History'!T16:V16)))/MAX('2. Demand History'!W16,1),3) -> 0 | O16: =ROUND(ABS('2. Demand History'!X16-IF($D16="Yes",'2. Demand History'!L16,AVERAGE('2. Demand History'!U16:W16)))/MAX('2. Demand History'!X16,1),3) -> 0 | P16: =ROUND(ABS('2. Demand History'!Y16-IF($D16="Yes",'2. Demand History'!M16,AVERAGE('2. Demand History'!V16:X16)))/MAX('2. Demand History'!Y16,1),3) -> 0.091 | Q16: =ROUND(ABS('2. Demand History'!Z16-IF($D16="Yes",'2. Demand History'!N16,AVERAGE('2. Demand History'!W16:Y16)))/MAX('2. Demand History'!Z16,1),3) -> 0.091
... A504: ='2. Demand History'!A504 -> NT10500 | B504: ='2. Demand History'!B504 -> Phone Case Clear V670 | C504: ='1. Master Data'!C504 -> Accessories | D504: No | E504: =IF(D504="Yes","Seasonal Naive","Moving Avg 3") -> Moving Avg 3 | F504: =ROUND(AVERAGE('2. Demand History'!O504:Z504),1) -> 246.8 | G504: =ROUND(STDEV('2. Demand History'!O504:Z504),1) -> 15.8 | H504: =IF(F504=0,0,ROUND(G504/F504,2)) -> 0.06 | I504: =ROUND(SUM('2. Demand History'!O504:Z504)/MAX(SUM('2. Demand History'!C504:N504),1),2) -> 1.05 | J504: =IF(D504="Yes",ROUND('2. Demand History'!O504*I504,0),ROUND(AVERAGE('2. Demand History'!X504:Z504),0)) -> 249 | K504: =ROUND(AVERAGE(L504:Q504),3) -> 0.068 | L504: =ROUND(ABS('2. Demand History'!U504-IF($D504="Yes",'2. Demand History'!I504,AVERAGE('2. Demand History'!R504:T504)))/MAX('2. Demand History'!U504,1),3) -> 0.101 | M504: =ROUND(ABS('2. Demand History'!V504-IF($D504="Yes",'2. Demand History'!J504,AVERAGE('2. Demand History'!S504:U504)))/MAX('2. Demand History'!V504,1),3) -> 0.03 | N504: =ROUND(ABS('2. Demand History'!W504-IF($D504="Yes",'2. Demand History'!K504,AVERAGE('2. Demand History'!T504:V504)))/MAX('2. Demand History'!W504,1),3) -> 0.066 | O504: =ROUND(ABS('2. Demand History'!X504-IF($D504="Yes",'2. Demand History'!L504,AVERAGE('2. Demand History'!U504:W504)))/MAX('2. Demand History'!X504,1),3) -> 0.044 | P504: =ROUND(ABS('2. Demand History'!Y504-IF($D504="Yes",'2. Demand History'!M504,AVERAGE('2. Demand History'!V504:X504)))/MAX('2. Demand History'!Y504,1),3) -> 0.07 | Q504: =ROUND(ABS('2. Demand History'!Z504-IF($D504="Yes",'2. Demand History'!N504,AVERAGE('2. Demand History'!W504:Y504)))/MAX('2. Demand History'!Z504,1),3) -> 0.095
A506: FORMULA REFERENCE
A507: Method: seasonal SKUs forecast with Seasonal Naive (same month last year times YoY growth). Stable SKUs use a 3 month Moving Average.
A508: Forecast Jun 26 = IF seasonal, Jun 25 demand x YoY growth, ELSE average of Mar to May 26.
A509: MAPE = average of the 6 monthly backtest errors. Err month = ABS(actual minus method forecast) / actual.
A510: Read: green under 10 percent is strong, amber 10 to 25 is workable, red over 25 means the part is erratic. Erratic Z items are managed with a Min Max policy instead of a forecast (see Replenishment).

Sheet 4. ABC XYZ Analysis
A1: ABC XYZ ANALYSIS
A2: ABC ranks value concentration. XYZ measures demand predictability. Together they set the stocking strategy.
A4: SKU | B4: Product Name | C4: Category | D4: DC | E4: Unit Cost | F4: Annual Usage | G4: ACV | H4: Rank | I4: Cum ACV | J4: Cum % | K4: ABC | L4: CV | M4: XYZ | N4: Class
A5: ='1. Master Data'!A76 -> NT10072 | B5: ='1. Master Data'!B76 -> CreatorPro 629 i9 16in | C5: ='1. Master Data'!C76 -> Laptops | D5: ='1. Master Data'!D76 -> East DC | E5: ='1. Master Data'!F76 -> 1121 | F5: ='2. Demand History'!AA76 -> 3089 | G5: =E5*F5 -> 3462769 | H5: =RANK(G5,G$5:G$504,0) -> 1 | I5: =SUMPRODUCT((H$5:H$504<=H5)*G$5:G$504) -> 3462769 | J5: =I5/SUM(G$5:G$504) -> 0.020943102 | K5: =IF(J5<=0.8,"A",IF(J5<=0.95,"B","C")) -> A | L5: ='3. Demand Forecast'!H76 -> 0.31 | M5: =IF(L5<=0.25,"X",IF(L5<=0.6,"Y","Z")) -> Y | N5: =K5&M5 -> AY
A6: ='1. Master Data'!A108 -> NT10104 | B6: ='1. Master Data'!B108 -> VisionLED 501in 4K | C6: ='1. Master Data'!C108 -> TVs | D6: ='1. Master Data'!D108 -> East DC | E6: ='1. Master Data'!F108 -> 1395 | F6: ='2. Demand History'!AA108 -> 2259 | G6: =E6*F6 -> 3151305 | H6: =RANK(G6,G$5:G$504,0) -> 2 | I6: =SUMPRODUCT((H$5:H$504<=H6)*G$5:G$504) -> 6614074 | J6: =I6/SUM(G$5:G$504) -> 0.040002444 | K6: =IF(J6<=0.8,"A",IF(J6<=0.95,"B","C")) -> A | L6: ='3. Demand Forecast'!H108 -> 0.31 | M6: =IF(L6<=0.25,"X",IF(L6<=0.6,"Y","Z")) -> Y | N6: =K6&M6 -> AY
A7: ='1. Master Data'!A32 -> NT10028 | B7: ='1. Master Data'!B32 -> Nova X761 Pro 256GB | C7: ='1. Master Data'!C32 -> Smartphones | D7: ='1. Master Data'!D32 -> East DC | E7: ='1. Master Data'!F32 -> 779 | F7: ='2. Demand History'!AA32 -> 3921 | G7: =E7*F7 -> 3054459 | H7: =RANK(G7,G$5:G$504,0) -> 3 | I7: =SUMPRODUCT((H$5:H$504<=H7)*G$5:G$504) -> 9668533 | J7: =I7/SUM(G$5:G$504) -> 0.058476055 | K7: =IF(J7<=0.8,"A",IF(J7<=0.95,"B","C")) -> A | L7: ='3. Demand Forecast'!H32 -> 0.35 | M7: =IF(L7<=0.25,"X",IF(L7<=0.6,"Y","Z")) -> Y | N7: =K7&M7 -> AY
A8: ='1. Master Data'!A143 -> NT10139 | B8: ='1. Master Data'!B143 -> VisionQ 920in QLED | C8: ='1. Master Data'!C143 -> TVs | D8: ='1. Master Data'!D143 -> Central DC | E8: ='1. Master Data'!F143 -> 1097 | F8: ='2. Demand History'!AA143 -> 2627 | G8: =E8*F8 -> 2881819 | H8: =RANK(G8,G$5:G$504,0) -> 4 | I8: =SUMPRODUCT((H$5:H$504<=H8)*G$5:G$504) -> 12550352 | J8: =I8/SUM(G$5:G$504) -> 0.075905525 | K8: =IF(J8<=0.8,"A",IF(J8<=0.95,"B","C")) -> A | L8: ='3. Demand Forecast'!H143 -> 0.27 | M8: =IF(L8<=0.25,"X",IF(L8<=0.6,"Y","Z")) -> Y | N8: =K8&M8 -> AY
A9: ='1. Master Data'!A55 -> NT10051 | B9: ='1. Master Data'!B55 -> CreatorPro 982 i9 16in | C9: ='1. Master Data'!C55 -> Laptops | D9: ='1. Master Data'!D55 -> Central DC | E9: ='1. Master Data'!F55 -> 1137 | F9: ='2. Demand History'!AA55 -> 2197 | G9: =E9*F9 -> 2497989 | H9: =RANK(G9,G$5:G$504,0) -> 5 | I9: =SUMPRODUCT((H$5:H$504<=H9)*G$5:G$504) -> 15048341 | J9: =I9/SUM(G$5:G$504) -> 0.09101356 | K9: =IF(J9<=0.8,"A",IF(J9<=0.95,"B","C")) -> A | L9: ='3. Demand Forecast'!H55 -> 0.3 | M9: =IF(L9<=0.25,"X",IF(L9<=0.6,"Y","Z")) -> Y | N9: =K9&M9 -> AY
A10: ='1. Master Data'!A30 -> NT10026 | B10: ='1. Master Data'!B30 -> Edge 712 5G 128GB | C10: ='1. Master Data'!C30 -> Smartphones | D10: ='1. Master Data'!D30 -> East DC | E10: ='1. Master Data'!F30 -> 321 | F10: ='2. Demand History'!AA30 -> 6808 | G10: =E10*F10 -> 2185368 | H10: =RANK(G10,G$5:G$504,0) -> 6 | I10: =SUMPRODUCT((H$5:H$504<=H10)*G$5:G$504) -> 17233709 | J10: =I10/SUM(G$5:G$504) -> 0.10423084 | K10: =IF(J10<=0.8,"A",IF(J10<=0.95,"B","C")) -> A | L10: ='3. Demand Forecast'!H30 -> 0.31 | M10: =IF(L10<=0.25,"X",IF(L10<=0.6,"Y","Z")) -> Y | N10: =K10&M10 -> AY
A11: ='1. Master Data'!A400 -> NT10396 | B11: ='1. Master Data'!B400 -> MirrorlessM 229 | C11: ='1. Master Data'!C400 -> Cameras | D11: ='1. Master Data'!D400 -> Central DC | E11: ='1. Master Data'!F400 -> 1120 | F11: ='2. Demand History'!AA400 -> 1911 | G11: =E11*F11 -> 2140320 | H11: =RANK(G11,G$5:G$504,0) -> 7 | I11: =SUMPRODUCT((H$5:H$504<=H11)*G$5:G$504) -> 19374029 | J11: =I11/SUM(G$5:G$504) -> 0.11717566 | K11: =IF(J11<=0.8,"A",IF(J11<=0.95,"B","C")) -> A | L11: ='3. Demand Forecast'!H400 -> 0.25 | M11: =IF(L11<=0.25,"X",IF(L11<=0.6,"Y","Z")) -> X | N11: =K11&M11 -> AX
A12: ='1. Master Data'!A160 -> NT10156 | B12: ='1. Master Data'!B160 -> ClipMic 445 Wireless | C12: ='1. Master Data'!C160 -> Audio | D12: ='1. Master Data'!D160 -> West DC | E12: ='1. Master Data'!F160 -> 250 | F12: ='2. Demand History'!AA160 -> 7215 | G12: =E12*F12 -> 1803750 | H12: =RANK(G12,G$5:G$504,0) -> 8 | I12: =SUMPRODUCT((H$5:H$504<=H12)*G$5:G$504) -> 21177779 | J12: =I12/SUM(G$5:G$504) -> 0.12808489 | K12: =IF(J12<=0.8,"A",IF(J12<=0.95,"B","C")) -> A | L12: ='3. Demand Forecast'!H160 -> 0.27 | M12: =IF(L12<=0.25,"X",IF(L12<=0.6,"Y","Z")) -> Y | N12: =K12&M12 -> AY
A13: ='1. Master Data'!A39 -> NT10035 | B13: ='1. Master Data'!B39 -> Nova X683 Pro 256GB | C13: ='1. Master Data'!C39 -> Smartphones | D13: ='1. Master Data'!D39 -> East DC | E13: ='1. Master Data'!F39 -> 524 | F13: ='2. Demand History'!AA39 -> 3400 | G13: =E13*F13 -> 1781600 | H13: =RANK(G13,G$5:G$504,0) -> 9 | I13: =SUMPRODUCT((H$5:H$504<=H13)*G$5:G$504) -> 22959379 | J13: =I13/SUM(G$5:G$504) -> 0.13886015 | K13: =IF(J13<=0.8,"A",IF(J13<=0.95,"B","C")) -> A | L13: ='3. Demand Forecast'!H39 -> 0.33 | M13: =IF(L13<=0.25,"X",IF(L13<=0.6,"Y","Z")) -> Y | N13: =K13&M13 -> AY
A14: ='1. Master Data'!A336 -> NT10332 | B14: ='1. Master Data'!B336 -> HomeCam 631 1080p | C14: ='1. Master Data'!C336 -> Smart Home | D14: ='1. Master Data'!D336 -> Central DC | E14: ='1. Master Data'!F336 -> 87 | F14: ='2. Demand History'!AA336 -> 20102 | G14: =E14*F14 -> 1748874 | H14: =RANK(G14,G$5:G$504,0) -> 10 | I14: =SUMPRODUCT((H$5:H$504<=H14)*G$5:G$504) -> 24708253 | J14: =I14/SUM(G$5:G$504) -> 0.14943747 | K14: =IF(J14<=0.8,"A",IF(J14<=0.95,"B","C")) -> A | L14: ='3. Demand Forecast'!H336 -> 0.06 | M14: =IF(L14<=0.25,"X",IF(L14<=0.6,"Y","Z")) -> X | N14: =K14&M14 -> AX
A15: ='1. Master Data'!A291 -> NT10287 | B15: ='1. Master Data'!B291 -> ProMouse G661 | C15: ='1. Master Data'!C291 -> Gaming | D15: ='1. Master Data'!D291 -> Central DC | E15: ='1. Master Data'!F291 -> 190 | F15: ='2. Demand History'!AA291 -> 9156 | G15: =E15*F15 -> 1739640 | H15: =RANK(G15,G$5:G$504,0) -> 11 | I15: =SUMPRODUCT((H$5:H$504<=H15)*G$5:G$504) -> 26447893 | J15: =I15/SUM(G$5:G$504) -> 0.15995896 | K15: =IF(J15<=0.8,"A",IF(J15<=0.95,"B","C")) -> A | L15: ='3. Demand Forecast'!H291 -> 0.25 | M15: =IF(L15<=0.25,"X",IF(L15<=0.6,"Y","Z")) -> X | N15: =K15&M15 -> AX
A16: ='1. Master Data'!A70 -> NT10066 | B16: ='1. Master Data'!B70 -> UltraSlim 542 Ryzen 5 | C16: ='1. Master Data'!C70 -> Laptops | D16: ='1. Master Data'!D70 -> East DC | E16: ='1. Master Data'!F70 -> 1410 | F16: ='2. Demand History'!AA70 -> 1134 | G16: =E16*F16 -> 1598940 | H16: =RANK(G16,G$5:G$504,0) -> 12 | I16: =SUMPRODUCT((H$5:H$504<=H16)*G$5:G$504) -> 28046833 | J16: =I16/SUM(G$5:G$504) -> 0.16962947 | K16: =IF(J16<=0.8,"A",IF(J16<=0.95,"B","C")) -> A | L16: ='3. Demand Forecast'!H70 -> 0.3 | M16: =IF(L16<=0.25,"X",IF(L16<=0.6,"Y","Z")) -> Y | N16: =K16&M16 -> AY
A17: ='1. Master Data'!A103 -> NT10099 | B17: ='1. Master Data'!B103 -> WorkMate 633 i3 14in | C17: ='1. Master Data'!C103 -> Laptops | D17: ='1. Master Data'!D103 -> West DC | E17: ='1. Master Data'!F103 -> 1125 | F17: ='2. Demand History'!AA103 -> 1339 | G17: =E17*F17 -> 1506375 | H17: =RANK(G17,G$5:G$504,0) -> 13 | I17: =SUMPRODUCT((H$5:H$504<=H17)*G$5:G$504) -> 29553208 | J17: =I17/SUM(G$5:G$504) -> 0.17874015 | K17: =IF(J17<=0.8,"A",IF(J17<=0.95,"B","C")) -> A | L17: ='3. Demand Forecast'!H103 -> 0.33 | M17: =IF(L17<=0.25,"X",IF(L17<=0.6,"Y","Z")) -> Y | N17: =K17&M17 -> AY
A18: ='1. Master Data'!A129 -> NT10125 | B18: ='1. Master Data'!B129 -> VisionOLED 414in 4K | C18: ='1. Master Data'!C129 -> TVs | D18: ='1. Master Data'!D129 -> East DC | E18: ='1. Master Data'!F129 -> 1001 | F18: ='2. Demand History'!AA129 -> 1453 | G18: =E18*F18 -> 1454453 | H18: =RANK(G18,G$5:G$504,0) -> 14 | I18: =SUMPRODUCT((H$5:H$504<=H18)*G$5:G$504) -> 31007661 | J18: =I18/SUM(G$5:G$504) -> 0.18753679 | K18: =IF(J18<=0.8,"A",IF(J18<=0.95,"B","C")) -> A | L18: ='3. Demand Forecast'!H129 -> 0.29 | M18: =IF(L18<=0.25,"X",IF(L18<=0.6,"Y","Z")) -> Y | N18: =K18&M18 -> AY
A19: ='1. Master Data'!A156 -> NT10152 | B19: ='1. Master Data'!B156 -> StudioPods 426 ANC | C19: ='1. Master Data'!C156 -> Audio | D19: ='1. Master Data'!D156 -> West DC | E19: ='1. Master Data'!F156 -> 236 | F19: ='2. Demand History'!AA156 -> 6116 | G19: =E19*F19 -> 1443376 | H19: =RANK(G19,G$5:G$504,0) -> 15 | I19: =SUMPRODUCT((H$5:H$504<=H19)*G$5:G$504) -> 32451037 | J19: =I19/SUM(G$5:G$504) -> 0.19626645 | K19: =IF(J19<=0.8,"A",IF(J19<=0.95,"B","C")) -> A | L19: ='3. Demand Forecast'!H156 -> 0.27 | M19: =IF(L19<=0.25,"X",IF(L19<=0.6,"Y","Z")) -> Y | N19: =K19&M19 -> AY
A20: ='1. Master Data'!A22 -> NT10018 | B20: ='1. Master Data'!B22 -> Nova X223 Pro 256GB | C20: ='1. Master Data'!C22 -> Smartphones | D20: ='1. Master Data'!D22 -> West DC | E20: ='1. Master Data'!F22 -> 809 | F20: ='2. Demand History'!AA22 -> 1739 | G20: =E20*F20 -> 1406851 | H20: =RANK(G20,G$5:G$504,0) -> 16 | I20: =SUMPRODUCT((H$5:H$504<=H20)*G$5:G$504) -> 33857888 | J20: =I20/SUM(G$5:G$504) -> 0.20477519 | K20: =IF(J20<=0.8,"A",IF(J20<=0.95,"B","C")) -> A | L20: ='3. Demand Forecast'!H22 -> 0.28 | M20: =IF(L20<=0.25,"X",IF(L20<=0.6,"Y","Z")) -> Y | N20: =K20&M20 -> AY
A21: ='1. Master Data'!A48 -> NT10044 | B21: ='1. Master Data'!B48 -> Nova Lite 886 64GB | C21: ='1. Master Data'!C48 -> Smartphones | D21: ='1. Master Data'!D48 -> Central DC | E21: ='1. Master Data'!F48 -> 849 | F21: ='2. Demand History'!AA48 -> 1607 | G21: =E21*F21 -> 1364343 | H21: =RANK(G21,G$5:G$504,0) -> 17 | I21: =SUMPRODUCT((H$5:H$504<=H21)*G$5:G$504) -> 35222231 | J21: =I21/SUM(G$5:G$504) -> 0.21302685 | K21: =IF(J21<=0.8,"A",IF(J21<=0.95,"B","C")) -> A | L21: ='3. Demand Forecast'!H48 -> 0.37 | M21: =IF(L21<=0.25,"X",IF(L21<=0.6,"Y","Z")) -> Y | N21: =K21&M21 -> AY
A22: ='1. Master Data'!A12 -> NT10008 | B22: ='1. Master Data'!B12 -> Edge 637 5G 128GB | C22: ='1. Master Data'!C12 -> Smartphones | D22: ='1. Master Data'!D12 -> West DC | E22: ='1. Master Data'!F12 -> 827 | F22: ='2. Demand History'!AA12 -> 1629 | G22: =E22*F22 -> 1347183 | H22: =RANK(G22,G$5:G$504,0) -> 18 | I22: =SUMPRODUCT((H$5:H$504<=H22)*G$5:G$504) -> 36569414 | J22: =I22/SUM(G$5:G$504) -> 0.22117472 | K22: =IF(J22<=0.8,"A",IF(J22<=0.95,"B","C")) -> A | L22: ='3. Demand Forecast'!H12 -> 0.37 | M22: =IF(L22<=0.25,"X",IF(L22<=0.6,"Y","Z")) -> Y | N22: =K22&M22 -> AY
A23: ='1. Master Data'!A153 -> NT10149 | B23: ='1. Master Data'!B153 -> CinemaMax 755in 8K | C23: ='1. Master Data'!C153 -> TVs | D23: ='1. Master Data'!D153 -> East DC | E23: ='1. Master Data'!F153 -> 1759 | F23: ='2. Demand History'!AA153 -> 763 | G23: =E23*F23 -> 1342117 | H23: =RANK(G23,G$5:G$504,0) -> 19 | I23: =SUMPRODUCT((H$5:H$504<=H23)*G$5:G$504) -> 37911531 | J23: =I23/SUM(G$5:G$504) -> 0.22929195 | K23: =IF(J23<=0.8,"A",IF(J23<=0.95,"B","C")) -> A | L23: ='3. Demand Forecast'!H153 -> 0.27 | M23: =IF(L23<=0.25,"X",IF(L23<=0.6,"Y","Z")) -> Y | N23: =K23&M23 -> AY
A24: ='1. Master Data'!A41 -> NT10037 | B24: ='1. Master Data'!B41 -> Nova X618 128GB | C24: ='1. Master Data'!C41 -> Smartphones | D24: ='1. Master Data'!D41 -> Central DC | E24: ='1. Master Data'!F41 -> 852 | F24: ='2. Demand History'!AA41 -> 1489 | G24: =E24*F24 -> 1268628 | H24: =RANK(G24,G$5:G$504,0) -> 20 | I24: =SUMPRODUCT((H$5:H$504<=H24)*G$5:G$504) -> 39180159 | J24: =I24/SUM(G$5:G$504) -> 0.23696471 | K24: =IF(J24<=0.8,"A",IF(J24<=0.95,"B","C")) -> A | L24: ='3. Demand Forecast'!H41 -> 0.24 | M24: =IF(L24<=0.25,"X",IF(L24<=0.6,"Y","Z")) -> X | N24: =K24&M24 -> AX
A25: ='1. Master Data'!A204 -> NT10200 | B25: ='1. Master Data'!B204 -> WaveBar 886 Soundbar | C25: ='1. Master Data'!C204 -> Audio | D25: ='1. Master Data'!D204 -> East DC | E25: ='1. Master Data'!F204 -> 207 | F25: ='2. Demand History'!AA204 -> 5604 | G25: =E25*F25 -> 1160028 | H25: =RANK(G25,G$5:G$504,0) -> 21 | I25: =SUMPRODUCT((H$5:H$504<=H25)*G$5:G$504) -> 40340187 | J25: =I25/SUM(G$5:G$504) -> 0.24398065 | K25: =IF(J25<=0.8,"A",IF(J25<=0.95,"B","C")) -> A | L25: ='3. Demand Forecast'!H204 -> 0.23 | M25: =IF(L25<=0.25,"X",IF(L25<=0.6,"Y","Z")) -> X | N25: =K25&M25 -> AX
A26: ='1. Master Data'!A246 -> NT10242 | B26: ='1. Master Data'!B246 -> PulseRing 393 | C26: ='1. Master Data'!C246 -> Wearables | D26: ='1. Master Data'!D246 -> East DC | E26: ='1. Master Data'!F246 -> 103 | F26: ='2. Demand History'!AA246 -> 11197 | G26: =E26*F26 -> 1153291 | H26: =RANK(G26,G$5:G$504,0) -> 22 | I26: =SUMPRODUCT((H$5:H$504<=H26)*G$5:G$504) -> 41493478 | J26: =I26/SUM(G$5:G$504) -> 0.25095585 | K26: =IF(J26<=0.8,"A",IF(J26<=0.95,"B","C")) -> A | L26: ='3. Demand Forecast'!H246 -> 0.3 | M26: =IF(L26<=0.25,"X",IF(L26<=0.6,"Y","Z")) -> Y | N26: =K26&M26 -> AY
A27: ='1. Master Data'!A63 -> NT10059 | B27: ='1. Master Data'!B63 -> WorkMate 293 i3 14in | C27: ='1. Master Data'!C63 -> Laptops | D27: ='1. Master Data'!D63 -> West DC | E27: ='1. Master Data'!F63 -> 1383 | F27: ='2. Demand History'!AA63 -> 822 | G27: =E27*F27 -> 1136826 | H27: =RANK(G27,G$5:G$504,0) -> 23 | I27: =SUMPRODUCT((H$5:H$504<=H27)*G$5:G$504) -> 42630304 | J27: =I27/SUM(G$5:G$504) -> 0.25783146 | K27: =IF(J27<=0.8,"A",IF(J27<=0.95,"B","C")) -> A | L27: ='3. Demand Forecast'!H63 -> 0.32 | M27: =IF(L27<=0.25,"X",IF(L27<=0.6,"Y","Z")) -> Y | N27: =K27&M27 -> AY
A28: ='1. Master Data'!A270 -> NT10266 | B28: ='1. Master Data'!B270 -> GameStation Controller 667 | C28: ='1. Master Data'!C270 -> Gaming | D28: ='1. Master Data'!D270 -> West DC | E28: ='1. Master Data'!F270 -> 281 | F28: ='2. Demand History'!AA270 -> 3957 | G28: =E28*F28 -> 1111917 | H28: =RANK(G28,G$5:G$504,0) -> 24 | I28: =SUMPRODUCT((H$5:H$504<=H28)*G$5:G$504) -> 43742221 | J28: =I28/SUM(G$5:G$504) -> 0.26455642 | K28: =IF(J28<=0.8,"A",IF(J28<=0.95,"B","C")) -> A | L28: ='3. Demand Forecast'!H270 -> 0.32 | M28: =IF(L28<=0.25,"X",IF(L28<=0.6,"Y","Z")) -> Y | N28: =K28&M28 -> AY
A29: ='1. Master Data'!A26 -> NT10022 | B29: ='1. Master Data'!B26 -> Pulse 521 Dual SIM | C29: ='1. Master Data'!C26 -> Smartphones | D29: ='1. Master Data'!D26 -> East DC | E29: ='1. Master Data'!F26 -> 782 | F29: ='2. Demand History'!AA26 -> 1417 | G29: =E29*F29 -> 1108094 | H29: =RANK(G29,G$5:G$504,0) -> 25 | I29: =SUMPRODUCT((H$5:H$504<=H29)*G$5:G$504) -> 44850315 | J29: =I29/SUM(G$5:G$504) -> 0.27125826 | K29: =IF(J29<=0.8,"A",IF(J29<=0.95,"B","C")) -> A | L29: ='3. Demand Forecast'!H26 -> 0.31 | M29: =IF(L29<=0.25,"X",IF(L29<=0.6,"Y","Z")) -> Y | N29: =K29&M29 -> AY
A30: ='1. Master Data'!A366 -> NT10362 | B30: ='1. Master Data'!B366 -> MirrorlessM 337 | C30: ='1. Master Data'!C366 -> Cameras | D30: ='1. Master Data'!D366 -> East DC | E30: ='1. Master Data'!F366 -> 1047 | F30: ='2. Demand History'!AA366 -> 1056 | G30: =E30*F30 -> 1105632 | H30: =RANK(G30,G$5:G$504,0) -> 26 | I30: =SUMPRODUCT((H$5:H$504<=H30)*G$5:G$504) -> 45955947 | J30: =I30/SUM(G$5:G$504) -> 0.27794521 | K30: =IF(J30<=0.8,"A",IF(J30<=0.95,"B","C")) -> A | L30: ='3. Demand Forecast'!H366 -> 0.26 | M30: =IF(L30<=0.25,"X",IF(L30<=0.6,"Y","Z")) -> Y | N30: =K30&M30 -> AY
A31: ='1. Master Data'!A285 -> NT10281 | B31: ='1. Master Data'!B285 -> StreamCam S631 | C31: ='1. Master Data'!C285 -> Gaming | D31: ='1. Master Data'!D285 -> West DC | E31: ='1. Master Data'!F285 -> 310 | F31: ='2. Demand History'!AA285 -> 3558 | G31: =E31*F31 -> 1102980 | H31: =RANK(G31,G$5:G$504,0) -> 27 | I31: =SUMPRODUCT((H$5:H$504<=H31)*G$5:G$504) -> 47058927 | J31: =I31/SUM(G$5:G$504) -> 0.28461612 | K31: =IF(J31<=0.8,"A",IF(J31<=0.95,"B","C")) -> A | L31: ='3. Demand Forecast'!H285 -> 0.3 | M31: =IF(L31<=0.25,"X",IF(L31<=0.6,"Y","Z")) -> Y | N31: =K31&M31 -> AY
A32: ='1. Master Data'!A107 -> NT10103 | B32: ='1. Master Data'!B107 -> VisionLED 495in 4K | C32: ='1. Master Data'!C107 -> TVs | D32: ='1. Master Data'!D107 -> East DC | E32: ='1. Master Data'!F107 -> 1280 | F32: ='2. Demand History'!AA107 -> 855 | G32: =E32*F32 -> 1094400 | H32: =RANK(G32,G$5:G$504,0) -> 28 | I32: =SUMPRODUCT((H$5:H$504<=H32)*G$5:G$504) -> 48153327 | J32: =I32/SUM(G$5:G$504) -> 0.29123514 | K32: =IF(J32<=0.8,"A",IF(J32<=0.95,"B","C")) -> A | L32: ='3. Demand Forecast'!H107 -> 0.34 | M32: =IF(L32<=0.25,"X",IF(L32<=0.6,"Y","Z")) -> Y | N32: =K32&M32 -> AY
A33: ='1. Master Data'!A14 -> NT10010 | B33: ='1. Master Data'!B14 -> Nova X834 128GB | C33: ='1. Master Data'!C14 -> Smartphones | D33: ='1. Master Data'!D14 -> West DC | E33: ='1. Master Data'!F14 -> 395 | F33: ='2. Demand History'!AA14 -> 2758 | G33: =E33*F33 -> 1089410 | H33: =RANK(G33,G$5:G$504,0) -> 29 | I33: =SUMPRODUCT((H$5:H$504<=H33)*G$5:G$504) -> 49242737 | J33: =I33/SUM(G$5:G$504) -> 0.29782398 | K33: =IF(J33<=0.8,"A",IF(J33<=0.95,"B","C")) -> A | L33: ='3. Demand Forecast'!H14 -> 0.32 | M33: =IF(L33<=0.25,"X",IF(L33<=0.6,"Y","Z")) -> Y | N33: =K33&M33 -> AY
A34: ='1. Master Data'!A51 -> NT10047 | B34: ='1. Master Data'!B51 -> Edge 345 5G 128GB | C34: ='1. Master Data'!C51 -> Smartphones | D34: ='1. Master Data'!D51 -> West DC | E34: ='1. Master Data'!F51 -> 474 | F34: ='2. Demand History'!AA51 -> 2282 | G34: =E34*F34 -> 1081668 | H34: =RANK(G34,G$5:G$504,0) -> 30 | I34: =SUMPRODUCT((H$5:H$504<=H34)*G$5:G$504) -> 50324405 | J34: =I34/SUM(G$5:G$504) -> 0.30436599 | K34: =IF(J34<=0.8,"A",IF(J34<=0.95,"B","C")) -> A | L34: ='3. Demand Forecast'!H51 -> 0.3 | M34: =IF(L34<=0.25,"X",IF(L34<=0.6,"Y","Z")) -> Y | N34: =K34&M34 -> AY
A35: ='1. Master Data'!A80 -> NT10076 | B35: ='1. Master Data'!B80 -> CreatorPro 809 i9 16in | C35: ='1. Master Data'!C80 -> Laptops | D35: ='1. Master Data'!D80 -> Central DC | E35: ='1. Master Data'!F80 -> 423 | F35: ='2. Demand History'!AA80 -> 2543 | G35: =E35*F35 -> 1075689 | H35: =RANK(G35,G$5:G$504,0) -> 31 | I35: =SUMPRODUCT((H$5:H$504<=H35)*G$5:G$504) -> 51400094 | J35: =I35/SUM(G$5:G$504) -> 0.31087185 | K35: =IF(J35<=0.8,"A",IF(J35<=0.95,"B","C")) -> A | L35: ='3. Demand Forecast'!H80 -> 0.31 | M35: =IF(L35<=0.25,"X",IF(L35<=0.6,"Y","Z")) -> Y | N35: =K35&M35 -> AY
A36: ='1. Master Data'!A33 -> NT10029 | B36: ='1. Master Data'!B33 -> Edge 379 5G 128GB | C36: ='1. Master Data'!C33 -> Smartphones | D36: ='1. Master Data'!D33 -> East DC | E36: ='1. Master Data'!F33 -> 674 | F36: ='2. Demand History'!AA33 -> 1560 | G36: =E36*F36 -> 1051440 | H36: =RANK(G36,G$5:G$504,0) -> 32 | I36: =SUMPRODUCT((H$5:H$504<=H36)*G$5:G$504) -> 52451534 | J36: =I36/SUM(G$5:G$504) -> 0.31723104 | K36: =IF(J36<=0.8,"A",IF(J36<=0.95,"B","C")) -> A | L36: ='3. Demand Forecast'!H33 -> 0.33 | M36: =IF(L36<=0.25,"X",IF(L36<=0.6,"Y","Z")) -> Y | N36: =K36&M36 -> AY
A37: ='1. Master Data'!A68 -> NT10064 | B37: ='1. Master Data'!B68 -> ProBook 948 i7 15in | C37: ='1. Master Data'!C68 -> Laptops | D37: ='1. Master Data'!D68 -> East DC | E37: ='1. Master Data'!F68 -> 1333 | F37: ='2. Demand History'!AA68 -> 788 | G37: =E37*F37 -> 1050404 | H37: =RANK(G37,G$5:G$504,0) -> 33 | I37: =SUMPRODUCT((H$5:H$504<=H37)*G$5:G$504) -> 53501938 | J37: =I37/SUM(G$5:G$504) -> 0.32358397 | K37: =IF(J37<=0.8,"A",IF(J37<=0.95,"B","C")) -> A | L37: ='3. Demand Forecast'!H68 -> 0.31 | M37: =IF(L37<=0.25,"X",IF(L37<=0.6,"Y","Z")) -> Y | N37: =K37&M37 -> AY
A38: ='1. Master Data'!A406 -> NT10402 | B38: ='1. Master Data'!B406 -> NovaTab 904 10in | C38: ='1. Master Data'!C406 -> Tablets | D38: ='1. Master Data'!D406 -> West DC | E38: ='1. Master Data'!F406 -> 220 | F38: ='2. Demand History'!AA406 -> 4768 | G38: =E38*F38 -> 1048960 | H38: =RANK(G38,G$5:G$504,0) -> 34 | I38: =SUMPRODUCT((H$5:H$504<=H38)*G$5:G$504) -> 54550898 | J38: =I38/SUM(G$5:G$504) -> 0.32992816 | K38: =IF(J38<=0.8,"A",IF(J38<=0.95,"B","C")) -> A | L38: ='3. Demand Forecast'!H406 -> 0.27 | M38: =IF(L38<=0.25,"X",IF(L38<=0.6,"Y","Z")) -> Y | N38: =K38&M38 -> AY
A39: ='1. Master Data'!A348 -> NT10344 | B39: ='1. Master Data'!B348 -> LumiBulb 614 RGB | C39: ='1. Master Data'!C348 -> Smart Home | D39: ='1. Master Data'!D348 -> West DC | E39: ='1. Master Data'!F348 -> 100 | F39: ='2. Demand History'!AA348 -> 10331 | G39: =E39*F39 -> 1033100 | H39: =RANK(G39,G$5:G$504,0) -> 35 | I39: =SUMPRODUCT((H$5:H$504<=H39)*G$5:G$504) -> 55583998 | J39: =I39/SUM(G$5:G$504) -> 0.33617643 | K39: =IF(J39<=0.8,"A",IF(J39<=0.95,"B","C")) -> A | L39: ='3. Demand Forecast'!H348 -> 0.07 | M39: =IF(L39<=0.25,"X",IF(L39<=0.6,"Y","Z")) -> X | N39: =K39&M39 -> AX
A40: ='1. Master Data'!A331 -> NT10327 | B40: ='1. Master Data'!B331 -> LumiBulb 401 RGB | C40: ='1. Master Data'!C331 -> Smart Home | D40: ='1. Master Data'!D331 -> East DC | E40: ='1. Master Data'!F331 -> 93 | F40: ='2. Demand History'!AA331 -> 10850 | G40: =E40*F40 -> 1009050 | H40: =RANK(G40,G$5:G$504,0) -> 36 | I40: =SUMPRODUCT((H$5:H$504<=H40)*G$5:G$504) -> 56593048 | J40: =I40/SUM(G$5:G$504) -> 0.34227925 | K40: =IF(J40<=0.8,"A",IF(J40<=0.95,"B","C")) -> A | L40: ='3. Demand Forecast'!H331 -> 0.04 | M40: =IF(L40<=0.25,"X",IF(L40<=0.6,"Y","Z")) -> X | N40: =K40&M40 -> AX
A41: ='1. Master Data'!A138 -> NT10134 | B41: ='1. Master Data'!B138 -> CinemaMax 312in 8K | C41: ='1. Master Data'!C138 -> TVs | D41: ='1. Master Data'!D138 -> Central DC | E41: ='1. Master Data'!F138 -> 1402 | F41: ='2. Demand History'!AA138 -> 715 | G41: =E41*F41 -> 1002430 | H41: =RANK(G41,G$5:G$504,0) -> 37 | I41: =SUMPRODUCT((H$5:H$504<=H41)*G$5:G$504) -> 57595478 | J41: =I41/SUM(G$5:G$504) -> 0.34834202 | K41: =IF(J41<=0.8,"A",IF(J41<=0.95,"B","C")) -> A | L41: ='3. Demand Forecast'!H138 -> 0.31 | M41: =IF(L41<=0.25,"X",IF(L41<=0.6,"Y","Z")) -> Y | N41: =K41&M41 -> AY
...

Sheet 5. Replenishment Model
A1: REPLENISHMENT MODEL
A2: Safety stock, reorder point, EOQ and order flags for all 500 SKUs. Service level 95 percent. | S2: Z (95% SL) | T2: Workdays/Mo | U2: Order Cost $ | V2: Holding %
S3: 1.65 | T3: 22 | U3: 50 | V3: 0.25
A4: SKU | B4: Product Name | C4: DC | D4: ABC | E4: XYZ | F4: Unit Cost | G4: Lead Time | H4: Avg Daily | I4: SD Daily | J4: Safety Stock | K4: Reorder Point | L4: EOQ | M4: On Hand | N4: Days of Supply | O4: Flag | P4: Priority | Q4: Policy
A5: ='1. Master Data'!A5 -> NT10001 | B5: ='1. Master Data'!B5 -> Nova X427 128GB | C5: ='1. Master Data'!D5 -> West DC | D5: ='4. ABC XYZ Analysis'!K5 -> A | E5: ='4. ABC XYZ Analysis'!M5 -> Y | F5: ='1. Master Data'!F5 -> 865 | G5: ='1. Master Data'!G5 -> 17 | H5: ='3. Demand Forecast'!F5/$T$3 -> 4.3227273 | I5: ='3. Demand Forecast'!G5/SQRT($T$3) -> 6.8650631 | J5: =ROUNDUP($S$3*I5*SQRT(G5),0) -> 47 | K5: =ROUNDUP(H5*G5+J5,0) -> 121 | L5: =IF(F5=0,0,ROUNDUP(SQRT(2*'4. ABC XYZ Analysis'!F5*$U$3/(F5*$V$3)),0)) -> 38 | M5: ='1. Master Data'!I5 -> 124 | N5: =IF(H5=0,999,ROUND(M5/H5,0)) -> 29 | O5: =IF(M5<=K5,"ORDER NOW",IF(M5<=K5*1.2,"ORDER SOON","OK")) -> ORDER SOON | P5: =IF(O5="ORDER NOW",IF(D5="A","URGENT",IF(D5="B","HIGH","MEDIUM")),IF(O5="ORDER SOON",IF(D5="A","HIGH","MEDIUM"),"LOW")) -> HIGH | Q5: =IF(E5="Z","Min Max","Reorder Point") -> Reorder Point
A6: ='1. Master Data'!A6 -> NT10002 | B6: ='1. Master Data'!B6 -> Pulse 962 Dual SIM | C6: ='1. Master Data'!D6 -> East DC | D6: ='4. ABC XYZ Analysis'!K6 -> A | E6: ='4. ABC XYZ Analysis'!M6 -> Y | F6: ='1. Master Data'!F6 -> 701 | G6: ='1. Master Data'!G6 -> 44 | H6: ='3. Demand Forecast'!F6/$T$3 -> 2.4 | I6: ='3. Demand Forecast'!G6/SQRT($T$3) -> 3.3685713 | J6: =ROUNDUP($S$3*I6*SQRT(G6),0) -> 37 | K6: =ROUNDUP(H6*G6+J6,0) -> 143 | L6: =IF(F6=0,0,ROUNDUP(SQRT(2*'4. ABC XYZ Analysis'!F6*$U$3/(F6*$V$3)),0)) -> 36 | M6: ='1. Master Data'!I6 -> 146 | N6: =IF(H6=0,999,ROUND(M6/H6,0)) -> 61 | O6: =IF(M6<=K6,"ORDER NOW",IF(M6<=K6*1.2,"ORDER SOON","OK")) -> ORDER SOON | P6: =IF(O6="ORDER NOW",IF(D6="A","URGENT",IF(D6="B","HIGH","MEDIUM")),IF(O6="ORDER SOON",IF(D6="A","HIGH","MEDIUM"),"LOW")) -> HIGH | Q6: =IF(E6="Z","Min Max","Reorder Point") -> Reorder Point
A7: ='1. Master Data'!A7 -> NT10003 | B7: ='1. Master Data'!B7 -> Nova Lite 936 64GB | C7: ='1. Master Data'!D7 -> West DC | D7: ='4. ABC XYZ Analysis'!K7 -> A | E7: ='4. ABC XYZ Analysis'!M7 -> Y | F7: ='1. Master Data'!F7 -> 261 | G7: ='1. Master Data'!G7 -> 21 | H7: ='3. Demand Forecast'!F7/$T$3 -> 5.4909091 | I7: ='3. Demand Forecast'!G7/SQRT($T$3) -> 8.1016272 | J7: =ROUNDUP($S$3*I7*SQRT(G7),0) -> 62 | K7: =ROUNDUP(H7*G7+J7,0) -> 178 | L7: =IF(F7=0,0,ROUNDUP(SQRT(2*'4. ABC XYZ Analysis'!F7*$U$3/(F7*$V$3)),0)) -> 78 | M7: ='1. Master Data'!I7 -> 181 | N7: =IF(H7=0,999,ROUND(M7/H7,0)) -> 33 | O7: =IF(M7<=K7,"ORDER NOW",IF(M7<=K7*1.2,"ORDER SOON","OK")) -> ORDER SOON | P7: =IF(O7="ORDER NOW",IF(D7="A","URGENT",IF(D7="B","HIGH","MEDIUM")),IF(O7="ORDER SOON",IF(D7="A","HIGH","MEDIUM"),"LOW")) -> HIGH | Q7: =IF(E7="Z","Min Max","Reorder Point") -> Reorder Point
A8: ='1. Master Data'!A8 -> NT10004 | B8: ='1. Master Data'!B8 -> Nova Lite 315 64GB | C8: ='1. Master Data'!D8 -> West DC | D8: ='4. ABC XYZ Analysis'!K8 -> A | E8: ='4. ABC XYZ Analysis'!M8 -> Y | F8: ='1. Master Data'!F8 -> 606 | G8: ='1. Master Data'!G8 -> 39 | H8: ='3. Demand Forecast'!F8/$T$3 -> 3.0454545 | I8: ='3. Demand Forecast'!G8/SQRT($T$3) -> 5.2447376 | J8: =ROUNDUP($S$3*I8*SQRT(G8),0) -> 55 | K8: =ROUNDUP(H8*G8+J8,0) -> 174 | L8: =IF(F8=0,0,ROUNDUP(SQRT(2*'4. ABC XYZ Analysis'!F8*$U$3/(F8*$V$3)),0)) -> 42 | M8: ='1. Master Data'!I8 -> 177 | N8: =IF(H8=0,999,ROUND(M8/H8,0)) -> 58 | O8: =IF(M8<=K8,"ORDER NOW",IF(M8<=K8*1.2,"ORDER SOON","OK")) -> ORDER SOON | P8: =IF(O8="ORDER NOW",IF(D8="A","URGENT",IF(D8="B","HIGH","MEDIUM")),IF(O8="ORDER SOON",IF(D8="A","HIGH","MEDIUM"),"LOW")) -> HIGH | Q8: =IF(E8="Z","Min Max","Reorder Point") -> Reorder Point
A9: ='1. Master Data'!A9 -> NT10005 | B9: ='1. Master Data'!B9 -> Pulse 753 Dual SIM | C9: ='1. Master Data'!D9 -> Central DC | D9: ='4. ABC XYZ Analysis'!K9 -> A | E9: ='4. ABC XYZ Analysis'!M9 -> Y | F9: ='1. Master Data'!F9 -> 598 | G9: ='1. Master Data'!G9 -> 25 | H9: ='3. Demand Forecast'!F9/$T$3 -> 1.6 | I9: ='3. Demand Forecast'!G9/SQRT($T$3) -> 2.1320072 | J9: =ROUNDUP($S$3*I9*SQRT(G9),0) -> 18 | K9: =ROUNDUP(H9*G9+J9,0) -> 58 | L9: =IF(F9=0,0,ROUNDUP(SQRT(2*'4. ABC XYZ Analysis'!F9*$U$3/(F9*$V$3)),0)) -> 39 | M9: ='1. Master Data'!I9 -> 61 | N9: =IF(H9=0,999,ROUND(M9/H9,0)) -> 38 | O9: =IF(M9<=K9,"ORDER NOW",IF(M9<=K9*1.2,"ORDER SOON","OK")) -> ORDER SOON | P9: =IF(O9="ORDER NOW",IF(D9="A","URGENT",IF(D9="B","HIGH","MEDIUM")),IF(O9="ORDER SOON",IF(D9="A","HIGH","MEDIUM"),"LOW")) -> HIGH | Q9: =IF(E9="Z","Min Max","Reorder Point") -> Reorder Point
A10: ='1. Master Data'!A10 -> NT10006 | B10: ='1. Master Data'!B10 -> Edge 244 5G 128GB | C10: ='1. Master Data'!D10 -> Central DC | D10: ='4. ABC XYZ Analysis'!K10 -> A | E10: ='4. ABC XYZ Analysis'!M10 -> Y | F10: ='1. Master Data'!F10 -> 627 | G10: ='1. Master Data'!G10 -> 35 | H10: ='3. Demand Forecast'!F10/$T$3 -> 3.0090909 | I10: ='3. Demand Forecast'!G10/SQRT($T$3) -> 4.1147738 | J10: =ROUNDUP($S$3*I10*SQRT(G10),0) -> 41 | K10: =ROUNDUP(H10*G10+J10,0) -> 147 | L10: =IF(F10=0,0,ROUNDUP(SQRT(2*'4. ABC XYZ Analysis'!F10*$U$3/(F10*$V$3)),0)) -> 66 | M10: ='1. Master Data'!I10 -> 150 | N10: =IF(H10=0,999,ROUND(M10/H10,0)) -> 50 | O10: =IF(M10<=K10,"ORDER NOW",IF(M10<=K10*1.2,"ORDER SOON","OK")) -> ORDER SOON | P10: =IF(O10="ORDER NOW",IF(D10="A","URGENT",IF(D10="B","HIGH","MEDIUM")),IF(O10="ORDER SOON",IF(D10="A","HIGH","MEDIUM"),"LOW")) -> HIGH | Q10: =IF(E10="Z","Min Max","Reorder Point") -> Reorder Point
A11: ='1. Master Data'!A11 -> NT10007 | B11: ='1. Master Data'!B11 -> Pulse 667 Dual SIM | C11: ='1. Master Data'!D11 -> Central DC | D11: ='4. ABC XYZ Analysis'!K11 -> A | E11: ='4. ABC XYZ Analysis'!M11 -> X | F11: ='1. Master Data'!F11 -> 685 | G11: ='1. Master Data'!G11 -> 36 | H11: ='3. Demand Forecast'!F11/$T$3 -> 1.5636364 | I11: ='3. Demand Forecast'!G11/SQRT($T$3) -> 2.5797287 | J11: =ROUNDUP($S$3*I11*SQRT(G11),0) -> 26 | K11: =ROUNDUP(H11*G11+J11,0) -> 83 | L11: =IF(F11=0,0,ROUNDUP(SQRT(2*'4. ABC XYZ Analysis'!F11*$U$3/(F11*$V$3)),0)) -> 34 | M11: ='1. Master Data'!I11 -> 86 | N11: =IF(H11=0,999,ROUND(M11/H11,0)) -> 55 | O11: =IF(M11<=K11,"ORDER NOW",IF(M11<=K11*1.2,"ORDER SOON","OK")) -> ORDER SOON | P11: =IF(O11="ORDER NOW",IF(D11="A","URGENT",IF(D11="B","HIGH","MEDIUM")),IF(O11="ORDER SOON",IF(D11="A","HIGH","MEDIUM"),"LOW")) -> HIGH | Q11: =IF(E11="Z","Min Max","Reorder Point") -> Reorder Point
A12: ='1. Master Data'!A12 -> NT10008 | B12: ='1. Master Data'!B12 -> Edge 637 5G 128GB | C12: ='1. Master Data'!D12 -> West DC | D12: ='4. ABC XYZ Analysis'!K12 -> A | E12: ='4. ABC XYZ Analysis'!M12 -> Y | F12: ='1. Master Data'!F12 -> 827 | G12: ='1. Master Data'!G12 -> 41 | H12: ='3. Demand Forecast'!F12/$T$3 -> 6.1727273 | I12: ='3. Demand Forecast'!G12/SQRT($T$3) -> 10.787956 | J12: =ROUNDUP($S$3*I12*SQRT(G12),0) -> 114 | K12: =ROUNDUP(H12*G12+J12,0) -> 368 | L12: =IF(F12=0,0,ROUNDUP(SQRT(2*'4. ABC XYZ Analysis'!F12*$U$3/(F12*$V$3)),0)) -> 60 | M12: ='1. Master Data'!I12 -> 370 | N12: =IF(H12=0,999,ROUND(M12/H12,0)) -> 60 | O12: =IF(M12<=K12,"ORDER NOW",IF(M12<=K12*1.2,"ORDER SOON","OK")) -> ORDER SOON | P12: =IF(O12="ORDER NOW",IF(D12="A","URGENT",IF(D12="B","HIGH","MEDIUM")),IF(O12="ORDER SOON",IF(D12="A","HIGH","MEDIUM"),"LOW")) -> HIGH | Q12: =IF(E12="Z","Min Max","Reorder Point") -> Reorder Point
